Workbook

Sheet README
A1: This Google Sheet integrates visually interpreted data from Collect Earth Online (CEO), combined with a stratification to calculate estimates of deforestation and degradation with confidence intervals
A3: The sheet automatically collects column names and summarizes points, and uses strata areas from Google Earth Engine to make calculations at national, sub-national levels and by identified forest type
A4: The complete methodology, including all scripts is described here (in French) here: https://docs.google.com/document/d/1oGOAG-H-6nFh565Dp0bW2z1715TN7OL4ReVbOHmaknk/edit?usp=sharing
A5: For more information contact aurelie.shapiro@fao.org or remi.dannunzio@fao.org
A7: To initiate the calculations you only need to import the CEO file into the CEO-2015-2023 sheet using File -> Import.
A8: and then enter the strata areas from GEE for 2015-2022 and 2022-2023
A9: The column addresses are all automatically generated
G10: Classification Scheme
A11: Sheet Name | B11: Description | G11: Code DDD | H11: Groupe DDD | I11: Code SEPAL | J11: Code CollectEarth | K11: Code GEE | L11: Nom | M11: Nom Espanol | N11: Name English | O11: Description | P11: Description English | Q11: Color Name | R11: Color Code | S11: CAR | T11: CMR | U11: COD | V11: COG | W11: EQG | X11: GAB
A12: CEO 2015-2023 | B12: Cleaned data from SEPAL using the scripts: https://github.com/aurelgrooves/CAFI_DDD | G12: 1 | H12: Forêt | I12: 1 | J12: 1 | K12: 1 | L12: Forêt Dense | M12: Bosque denso | N12: Dense Forest | O12: Forêt dense humide primaire sur terre ferme, >60% arborée | P12: Dense humid primary forest on terra firme, >60% tree cover | Q12: darkgreen | R12: #006400 | S12: X | T12: X | U12: X | V12: X | W12: X | X12: X
A13: TNT 2015-2022 | B13: Sample based area estimation for 2015-2022 stratification | G13: 2 | H13: Forêt | I13: 2 | J13: 2 | K13: 2 | L13: Forêt Dense Sèche | M13: Bosque denso seco | N13: Dense Dry Forest | O13: Forêt dense, >60% couverture arborée avec des saisons sèches | P13: Dense forest, >60% tree cover with dry seasons | Q13: green | R13: #32cd32 | S13: X | T13: X | U13: X | X13: X
A14: TNT 2023 | B14: Sample based area estimation for 2023 stratification | G14: 3 | H14: Forêt | I14: 3 | J14: 3 | K14: 3 | L14: Forêt Secondaire | M14: Bosque secundario | N14: Secondary Forest | O14: Forêt ouvert 30-60% couverture arborée, dégradée ou secondaire | P14: Open forest 30-60% tree cover, degraded or secondary | Q14: lime green | R14: #00ff00 | S14: X | T14: X | U14: X | V14: X | W14: X | X14: X
A15: National Summary 2015-2023 | B15: National data compiled for all years with forest area, deforestation rate | G15: 4 | H15: Forêt | I15: 4 | J15: 4 | K15: 4 | L15: Forêt Claire Sèche | M15: Bosque claro Seco | N15: Dry Open Forest | O15: Forêt claire sèche 30-60% couverture arborée, avec des saisons sèches | P15: Dry open forest 30-60% tree cover, with dry seasons | Q15: sea green | R15: #2e8b57 | S15: X | T15: X | U15: X
A16: Prefectures TNT 2015-2022 | B16: Sample based area estimation for 2015-2022 by sub-national area (drop down with names in cell A1) | G16: 5 | H16: Forêt | I16: 1 | J16: 5 | K16: 5 | L16: Forêt Sub-Montagnarde | M16: Bosque sub-montañoso | N16: Sub-Montane Forest | O16: Forêt >30% de couverture arborée, 1100-1750m en altitude | P16: Forest >30% tree cover, 1100-1750m altitude | Q16: cadet blue | R16: #5f9ea0 | T16: X | U16: X | W16: X | X16: X
A17: Prefectures TNT 2023 | B17: Sample based area estimation for 2023 by sub-national area (drop down with names in cell A1) | G17: 6 | H17: Forêt | I17: 1 | J17: 6 | K17: 6 | L17: Forêt Montagnarde | M17: Bosque montañoso | N17: Montane Forest | O17: Forêt >30% de couverture arborée, >1750m en altitude | P17: Forest >30% tree cover, >1750m altitude | Q17: turquoise | R17: #30d5c8 | T17: X | U17: X | W17: X
A18: Prefecture Summary 2015-2023 | B18: Sub-national data compiled for all years | G18: 7 | H18: Forêt | I18: 5 | J18: 7 | K18: 7 | L18: Mangrove | M18: Manglar | N18: Mangrove | O18: Forêt >30% de couverture arborée, sol hydromorphe | P18: Forest >30% tree cover, hydromorphic soil | Q18: purple | R18: #8b008b | T18: X | U18: X | V18: X | W18: X | X18: X
A19: Forest Types TNT 2015-2022 | B19: Sample based area estimation for 2015-2022 by forest type | G19: 8 | H19: Forêt | I19: 6 | J19: 8 | K19: 8 | L19: Forêt Marécageuse | M19: Bosque pantanoso | N19: Swamp Forest | O19: Forêt marécageuse mixte >30% couverture arborée, sol inondée >9 mois | P19: Mixed swamp forest >30% tree cover, soil flooded >9 months | Q19: magenta | R19: #008081 | S19: X | T19: X | U19: X | V19: X | W19: X | X19: X
A20: Forest Types TNT 2023 | B20: Sample based area estimation for 2023 by forest type | G20: 9 | H20: Forêt | I20: 7 | J20: 9 | K20: 9 | L20: Forêt Galérie | M20: Bosque en galería | N20: Gallery Forest | O20: Foret ripicole en fond de vallée ou en bordure de rivière | P20: Riparian forest on valley floor or river bank | Q20: dark sea green | R20: #0C343D | S20: X | T20: X | U20: X | V20: X | W20: X | X20: X
A21: Forest Types Summary 2015-2023 | B21: Sample based area estimation for forest types compiled for all years | G21: 10 | H21: Forêt | I21: X | J21: 10 | K21: X | L21: Plantation Forestière Mature | M21: Plantación forestal madura | N21: Mature Forest Plantation | O21: Couverture arborée >15% végétation cultivée/gérée | P21: Tree cover >15% cultivated/managed vegetation | Q21: saddle brown | R21: #8b4513 | S21: X | T21: X | U21: X | V21: X | W21: X | X21: X
A22: <Prefecture name> TNT 2015-2022 | B22: Sub-national sample based area estimation for 2015-2022 stratification (1 sheet for each area) | G22: 11 | H22: Forêt | I22: 8 | J22: 11 | K22: 10 | L22: Savane Arborée | M22: Sabana arbórea | N22: Woodland Savanna | O22: Savane boisée 15-30% arboré et arbustive > définition nationale | P22: Wooded savannah 15-30% trees and shrubs > national definition | Q22: olive drab | R22: #6b8e23 | S22: X | T22: X | U22: X | V22: X
A23: <Prefecture name> TNT 2023 | B23: Sub-national sample based area estimation for 2023 stratification (1 sheet for each area) | G23: 12 | H23: Non-Forêt | I23: 9 | J23: 12 | K23: 11 | L23: Savane Arbustive | M23: Sabana arbustiva | N23: Shrubland Savanna | O23: Savane >15% arbustive | P23: Savannah >15% shrubby | Q23: pale golden rod | R23: #eee8aa | S23: X | T23: X | U23: X | V23: X | W23: X | X23: X
G24: 13 | H24: Non-Forêt | I24: 10 | J24: 13 | K24: 12 | L24: Savane Herbacée | M24: Sabana herbácea | N24: Grassland Savanna | O24: Savanne herbacée <15% arbustive ou arborée | P24: Herbaceous savannah <15% shrub or tree cover | Q24: khaki | R24: #c3b091 | S24: X | T24: X | U24: X | V24: X | W24: X | X24: X
A25: CEO 2015-2023 Column names | B25: Description | C25: Values | G25: 14 | H25: Non-Forêt | I25: 11 | J25: 14 | K25: 13 | L25: Prairie Aquatique | M25: Pradera acuática | N25: Aquatic Grassland | O25: Couverture herbacée aquatique ou régulièrement inondée | P25: Aquatic or regularly flooded herbaceous cover | Q25: steel blue | R25: #4682b4 | S25: X | T25: X | U25: X | V25: X | W25: X | X25: X
A26: UID | B26: unique identifier | C26: integer | G26: 15 | H26: Non-Forêt | I26: 12 | J26: 15 | K26: 14 | L26: Sols Nus - Végétation Éparse | M26: Suelo desnudo-Vegetación escasa | N26: Bare Land and Sparse Vegetation | O26: <15% végétation | P26: <15% vegetation | Q26: grey | R26: #808080 | S26: X | T26: X | U26: X | V26: X | W26: X | X26: X
A27: TNT_stratum_1522 | B27: Stratum number for 2015-2022 | C27: integer (1-5) | G27: 16 | H27: Non-Forêt | I27: 13 | J27: 16 | K27: 15 | L27: Terres Cultivées | M27: Tierras cultivadas | N27: Cultivated Areas | O27: Couverture arbustive cultivée >15% arbustif/herbacée/arborée | P27: Cultivated shrub cover >15% shrub/herbaceous/arboreal | Q27: tan | R27: #d2b48c | S27: X | T27: X | U27: X | V27: X | W27: X | X27: X
A28: TNT_stratum_2223 | B28: Straum number of 2022-2023 | C28: integer (1-5) | G28: 17 | H28: Non-Forêt | I28: 14 | J28: 17 | K28: 16 | L28: Zones Bâties | M28: Zonas edifiadas | N28: Built-up Areas | O28: Présence humaine | P28: Human presence | Q28: maroon | R28: #800000 | S28: X | T28: X | U28: X | V28: X | W28: X | X28: X
A29: ID | B29: identifier from the CEO project | C29: integer | G29: 18 | H29: Non-Forêt | I29: 15 | J29: 18 | K29: 17 | L29: Eau | M29: Agua | N29: Water | O29: Eau > 50% | P29: Water >50% | Q29: blue | R29: #0000ff | S29: X | T29: X | U29: X | V29: X | W29: X | X29: X
A30: plotid | B30: CEO plot id | C30: integer
A31: point_id | B31: eSBAE systematic grid point identifier | C31: integer
A32: sampleid | B32: identifier for 2023 points | C32: integer
A33: lon | B33: longitude coordinate | C33: decimal numeral
A34: lat | B34: latitude coordinate | C34: decimal numeral
A35: geometry | B35: geopandas geometry | C35: POINT (Lat,Lon)
A36: Ref_FNF_2015 | B36: Forest or non-forest in 2015 | C36: 0 (non-forest), 1 (forest)
A37: Ref_Regeneration | B37: Observed regeneration | C37: 0= no regeneration, 1 = regeneration
A38: Ref_Change_1522 | B38: Change observed 2015-2022 | C38: o=no change, 1= change
A39: Ref_Change_Type_1522 | B39: Type of change observed 2015-2022 | C39: Stable, NF (non-forest); Def (deforestation), Deg (degradation)
A40: ArtFor | B40: Artisanal forestry driver presence | C40: 1=present, 0=absent
A41: ArtMine | B41: Artisanal minitng driver presence | C41: 1=present, 0=absent
... A134: Prefecture (or Province) | B134: sub-national administration name | C134: Stable, NF (non-forest); Def####(deforestation year), Deg#### (degradation year)

Sheet CEO 2015-2023
A1: geometry | B1: UID | C1: TNT_stratum_1522 | D1: TNT_stratum_2223 | E1: ID | F1: plotid | G1: point_id | H1: sampleid | I1: lon | J1: lat | K1: Ref_FNF_2015 | L1: Ref_Regeneration | M1: Ref_Change_1522 | N1: Ref_Change_Type_1522 | O1: ArtFor | P1: ArtMine | Q1: InfraR | R1: Urb | S1: IndFor | T1: Other | U1: Other_Desc | V1: IndMine | W1: IndAg | X1: ArtAg | Y1: Ref_Year_1522 | Z1: Ref_NFtype_2015 | AA1: Ref_Ftype_2015 | AB1: collection | AC1: interpreted | AD1: Ref_LCover_2015 | AE1: Ref_Change_Year_1522 | AF1: Ref_Change_LCover_1522 | AG1: Def2016 | AH1: Def2017 | AI1: Def2018 | AJ1: Def2019 | AK1: Def2020 | AL1: Def2021 | AM1: Def2022 | AN1: Deg2016 | AO1: Deg2017 | AP1: Deg2018 | AQ1: Deg2019 | AR1: Deg2020 | AS1: Deg2021 | AT1: Deg2022 | AU1: Defall | AV1: Degall | AW1: Stable | AX1: NF | AY1: DensFor | AZ1: DensDryFor | BA1: SecFor | BB1: DryOpenFor | BC1: Mangrove | BD1: Swamp | BE1: Gallery | BF1: Plantation | BG1: Woodland | BH1: Shrubland | BI1: Grassland | BJ1: Aquatic | BK1: Bare | BL1: Cultivated | BM1: Builtup | BN1: Water | BO1: DensFor_Def | BP1: DensDryFor_Def | BQ1: SecFor_Def | BR1: DryOpenFor_Def | BS1: Mangrove_Def | BT1: Swamp_Def | BU1: Gallery_Def | BV1: Plantation_Def | BW1: Woodland_Def | BX1: DensFor_Deg | BY1: DensDryFor_Deg | BZ1: SecFor_Deg | CA1: DryOpenFor_Deg | CB1: Mangrove_Deg | CC1: Swamp_Deg | CD1: Gallery_Deg | CE1: Plantation_Deg | CF1: Woodland_Deg | CG1: DensFor_Stable | CH1: DensDryFor_Stable | CI1: SecFor_Stable | CJ1: DryOpenFor_Stable | CK1: Mangrove_Stable | CL1: Swamp_Stable | CM1: Gallery_Stable | CN1: Plantation_Stable | CO1: Woodland_Stable | CP1: ISO | CQ1: sampling | CR1: Ref_FNF_2022 | CS1: Ref_Change_2023 | CT1: Ref_Change_Type_2023 | CU1: Ref_NFtype_2022 | CV1: Ref_Ftype_2022 | CW1: Ref_LCover_2022 | CX1: Ref_Change_Year_2023 | CY1: Ref_Change_LCover_2023 | CZ1: Def2023 | DA1: Deg2023 | DB1: interpreted_qc | DC1: Ref_Change_Type_1523 | DD1: Ref_Change_Year_1523 | DE1: Prefecture
A2: POINT (15.352268 7.276064) | B2: 0 | C2: 1 | D2: 5 | E2: 0 | F2: 1722 | G2: 1722 | H2: 1722 | I2: 15.352268 | J2: 7.276064 | K2: 1 | M2: 1 | N2: Def | O2: 0 | P2: 0 | Q2: 0 | R2: 0 | S2: 0 | T2: 0 | V2: 0 | W2: 0 | X2: 1 | Y2: 2017 | AA2: 3 | AB2: coll_1522_1 | AC2: 1 | AD2: 3 | AE2: Def2017 | AF2: Def_3 | AG2: 0 | AH2: 1 | AI2: 0 | AJ2: 0 | AK2: 0 | AL2: 0 | AM2: 0 | AN2: 0 | AO2: 0 | AP2: 0 | AQ2: 0 | AR2: 0 | AS2: 0 | AT2: 0 | AU2: 1 | AV2: 0 | AW2: 0 | AX2: 0 | AY2: 0 | AZ2: 0 | BA2: 1 | BB2: 0 | BC2: 0 | BD2: 0 | BE2: 0 | BF2: 0 | BG2: 0 | BH2: 0 | BI2: 0 | BJ2: 0 | BK2: 0 | BL2: 0 | BM2: 0 | BN2: 0 | BO2: 0 | BP2: 0 | BQ2: 1 | BR2: 0 | BS2: 0 | BT2: 0 | BU2: 0 | BV2: 0 | BW2: 0 | BX2: 0 | BY2: 0 | BZ2: 0 | CA2: 0 | CB2: 0 | CC2: 0 | CD2: 0 | CE2: 0 | CF2: 0 | CG2: 0 | CH2: 0 | CI2: 0 | CJ2: 0 | CK2: 0 | CL2: 0 | CM2: 0 | CN2: 0 | CO2: 0 | CP2: CAF | CQ2: ceo_1522 | DC2: Def | DD2: Def2017 | DE2: Ouham Pendé
A3: POINT (22.98635 8.020981) | B3: 1 | C3: 1 | D3: 2 | E3: 1 | F3: 378369 | G3: 378369 | H3: 378369 | I3: 22.98635 | J3: 8.020981 | K3: 0 | L3: oui | M3: 0 | N3: NF | O3: 0 | P3: 0 | Q3: 0 | R3: 0 | S3: 0 | T3: 0 | V3: 0 | W3: 0 | X3: 0 | Z3: 12 | AB3: coll_1522_1 | AC3: 1 | AD3: 12 | AE3: NF | AF3: NF_12 | AG3: 0 | AH3: 0 | AI3: 0 | AJ3: 0 | AK3: 0 | AL3: 0 | AM3: 0 | AN3: 0 | AO3: 0 | AP3: 0 | AQ3: 0 | AR3: 0 | AS3: 0 | AT3: 0 | AU3: 0 | AV3: 0 | AW3: 0 | AX3: 1 | AY3: 0 | AZ3: 0 | BA3: 0 | BB3: 0 | BC3: 0 | BD3: 0 | BE3: 0 | BF3: 0 | BG3: 0 | BH3: 1 | BI3: 0 | BJ3: 0 | BK3: 0 | BL3: 0 | BM3: 0 | BN3: 0 | BO3: 0 | BP3: 0 | BQ3: 0 | BR3: 0 | BS3: 0 | BT3: 0 | BU3: 0 | BV3: 0 | BW3: 0 | BX3: 0 | BY3: 0 | BZ3: 0 | CA3: 0 | CB3: 0 | CC3: 0 | CD3: 0 | CE3: 0 | CF3: 0 | CG3: 0 | CH3: 0 | CI3: 0 | CJ3: 0 | CK3: 0 | CL3: 0 | CM3: 0 | CN3: 0 | CO3: 0 | CP3: CAF | CQ3: ceo_1522 | DC3: NF | DD3: NF | DE3: Haute-Kotto
A4: POINT (22.707893 7.550748) | B4: 2 | C4: 1 | D4: 1 | E4: 2 | F4: 376353 | G4: 376353 | H4: 376353 | I4: 22.707893 | J4: 7.550748 | K4: 0 | L4: oui | M4: 0 | N4: NF | O4: 0 | P4: 0 | Q4: 0 | R4: 0 | S4: 0 | T4: 0 | V4: 0 | W4: 0 | X4: 0 | Z4: 12 | AB4: coll_1522_1 | AC4: 1 | AD4: 12 | AE4: NF | AF4: NF_12 | AG4: 0 | AH4: 0 | AI4: 0 | AJ4: 0 | AK4: 0 | AL4: 0 | AM4: 0 | AN4: 0 | AO4: 0 | AP4: 0 | AQ4: 0 | AR4: 0 | AS4: 0 | AT4: 0 | AU4: 0 | AV4: 0 | AW4: 0 | AX4: 1 | AY4: 0 | AZ4: 0 | BA4: 0 | BB4: 0 | BC4: 0 | BD4: 0 | BE4: 0 | BF4: 0 | BG4: 0 | BH4: 1 | BI4: 0 | BJ4: 0 | BK4: 0 | BL4: 0 | BM4: 0 | BN4: 0 | BO4: 0 | BP4: 0 | BQ4: 0 | BR4: 0 | BS4: 0 | BT4: 0 | BU4: 0 | BV4: 0 | BW4: 0 | BX4: 0 | BY4: 0 | BZ4: 0 | CA4: 0 | CB4: 0 | CC4: 0 | CD4: 0 | CE4: 0 | CF4: 0 | CG4: 0 | CH4: 0 | CI4: 0 | CJ4: 0 | CK4: 0 | CL4: 0 | CM4: 0 | CN4: 0 | CO4: 0 | CP4: CAF | CQ4: ceo_1522 | DC4: NF | DD4: NF | DE4: Haute-Kotto

Sheet TNT 2015-2022
A1: CENTRAL AFRICAN REPUBLIC NATIONAL FOREST COVER CHANGE ESTIMATES FROM TNT
A2: Total Study Area (ha) | B2: =B11 -> 61805534 | I2: Summary
I3: Year | J3: Deforestation | K3: Year | L3: Degradation
A4: Time Period | B4: 1522 | I4: 2016 | J4: =AJ19 -> #N/A | K4: 2016 | L4: =AJ27 -> #N/A
A5: Stratum | B5: Area (ha) | C5: Weight | D5: # CEO points interpreted | I5: 2017 | J5: =AJ20 -> #N/A | K5: 2017 | L5: =AJ28 -> #N/A
A6: 1 | B6: ='Prefecture Summary 2015-2023'!C$19 -> 50116708 | C6: =B6/$B$11 -> 0.81087736 | D6: =COUNTIFS(INDIRECT("'" & $B$16 & "'!" & $B$17 & ":" & $B$17),A6,INDIRECT("'" & $B$16 & "'!" & $B$12 & ":" & $B$12), "*" & $B$4 & "*") -> 3 | I6: 2018 | J6: =AJ21 -> #N/A | K6: 2018 | L6: =AJ29 -> #N/A
A7: 2 | B7: ='Prefecture Summary 2015-2023'!D$19 -> 5225079 | C7: =B7/$B$11 -> 0.084540634 | D7: =COUNTIFS(INDIRECT("'" & $B$16 & "'!" & $B$17 & ":" & $B$17),A7,INDIRECT("'" & $B$16 & "'!" & $B$12 & ":" & $B$12), "*" & $B$4 & "*") -> 0 | I7: 2019 | J7: =AJ22 -> #N/A | K7: 2019 | L7: =AJ30 -> #N/A
A8: 3 | B8: ='Prefecture Summary 2015-2023'!E$19 -> 3936262 | C8: =B8/$B$11 -> 0.063687857 | D8: =COUNTIFS(INDIRECT("'" & $B$16 & "'!" & $B$17 & ":" & $B$17),A8,INDIRECT("'" & $B$16 & "'!" & $B$12 & ":" & $B$12), "*" & $B$4 & "*") -> 0 | I8: 2020 | J8: =AJ23 -> #N/A | K8: 2020 | L8: =AJ31 -> #N/A
A9: 4 | B9: ='Prefecture Summary 2015-2023'!F$19 -> 1904772 | C9: =B9/$B$11 -> 0.030818794 | D9: =COUNTIFS(INDIRECT("'" & $B$16 & "'!" & $B$17 & ":" & $B$17),A9,INDIRECT("'" & $B$16 & "'!" & $B$12 & ":" & $B$12), "*" & $B$4 & "*") -> 0 | I9: 2021 | J9: =AJ24 -> #N/A | K9: 2021 | L9: =AJ32 -> #N/A
A10: 5 | B10: ='Prefecture Summary 2015-2023'!G$19 -> 622713 | C10: =B10/$B$11 -> 0.01007536 | D10: =COUNTIFS(INDIRECT("'" & $B$16 & "'!" & $B$17 & ":" & $B$17),A10,INDIRECT("'" & $B$16 & "'!" & $B$12 & ":" & $B$12), "*" & $B$4 & "*") -> 0 | I10: 2022 | J10: =AJ25 -> #N/A | K10: 2022 | L10: =AJ33 -> #N/A
B11: =SUM(B6:B10) -> 61805534 | C11: =SUM(C6:C10) -> 1 | D11: =SUM(D6:D10) -> 3 | I11: 2023 | J11: =#REF! -> #REF! | K11: 2023 | L11: =#REF! -> #REF!
A12: collection | B12: {=IFERROR("$" & SUBSTITUTE(ADDRESS(1, MATCH(A12, INDIRECT("'" & $B$16 & "'!1:1"), 0), 4), "1", ""), "Not Found")} -> $AB
A14: Z value | B14: 1.645
A16: Sheet Name | B16: CEO 2015-2023
A17: TNT_stratum_1522 | B17: =IFERROR("$" & SUBSTITUTE(ADDRESS(1, MATCH(A17, INDIRECT("'" & $B$16 & "'!1:1"), 0), 4), "1", ""), "Not Found") -> $C | C17: # of CEO points in Strata | I17: Variance | N17: Average | S17: Error per class per strata | X17: Area per class per strata | AC17: Weighted Average
A18: Ref_Change_Year_1523 | B18: =IFERROR("$" & SUBSTITUTE(ADDRESS(1, MATCH(A18, INDIRECT("'" & $B$16 & "'!1:1"), 0), 4), "1", ""), "Not Found") -> $DD | C18: 1 | D18: 2 | E18: 3 | F18: 4 | G18: 5 | H18: Total | I18: 1 | J18: 2 | K18: 3 | L18: 4 | M18: 5 | N18: 1 | O18: 2 | P18: 3 | Q18: 4 | R18: 5 | S18: 1 | T18: 2 | U18: 3 | V18: 4 | W18: 5 | X18: 1 | Y18: 2 | Z18: 3 | AA18: 4 | AB18: 5 | AC18: 1 | AD18: 2 | AE18: 3 | AF18: 4 | AG18: 5 | AH18: Total Error (ha) | AI18: MOE (90% c.i.) | AJ18: Total Area (ha) | AK18: Total error in % | AL18: Total of Area (%)
A19: Def2016 | B19: =IFERROR("$" & SUBSTITUTE(ADDRESS(1, MATCH(A19, INDIRECT("'" & $B$16 & "'!1:1"), 0), 4), "1", ""), "Not Found") -> $AG | C19: =COUNTIFS(INDIRECT("'" & $B$16 & "'!" & $B$17 & ":" & $B$17),C$18,INDIRECT("'" & $B$16 & "'!" & $B$18 & ":" & $B$18),$A19,INDIRECT("'" & $B$16 & "'!" & $B$12 & ":" & $B$12), "*" & $B$4 & "*") -> 0 | D19: =COUNTIFS(INDIRECT("'" & $B$16 & "'!" & $B$17 & ":" & $B$17),D$18,INDIRECT("'" & $B$16 & "'!" & $B$18 & ":" & $B$18),$A19,INDIRECT("'" & $B$16 & "'!" & $B$12 & ":" & $B$12), "*" & $B$4 & "*") -> 0 | E19: =COUNTIFS(INDIRECT("'" & $B$16 & "'!" & $B$17 & ":" & $B$17),E$18,INDIRECT("'" & $B$16 & "'!" & $B$18 & ":" & $B$18),$A19,INDIRECT("'" & $B$16 & "'!" & $B$12 & ":" & $B$12), "*" & $B$4 & "*") -> 0 | F19: =COUNTIFS(INDIRECT("'" & $B$16 & "'!" & $B$17 & ":" & $B$17),F$18,INDIRECT("'" & $B$16 & "'!" & $B$18 & ":" & $B$18),$A19,INDIRECT("'" & $B$16 & "'!" & $B$12 & ":" & $B$12), "*" & $B$4 & "*") -> 0 | G19: =COUNTIFS(INDIRECT("'" & $B$16 & "'!" & $B$17 & ":" & $B$17),G$18,INDIRECT("'" & $B$16 & "'!" & $B$18 & ":" & $B$18),$A19,INDIRECT("'" & $B$16 & "'!" & $B$12 & ":" & $B$12), "*" & $B$4 & "*") -> 0 | H19: =SUM(C19:G19) -> 0 | I19: =IFERROR(__xludf.DUMMYFUNCTION("IF($D$6=0, 0, VAR.S( FILTER( INDIRECT(""'"" & $B$16 & ""'!"" & $B19 & "":"" & $B19), (INDIRECT(""'"" & $B$16 & ""'!"" & $B$17 & "":"" & $B$17) = I$18) * (ISNUMBER(SEARCH($B$4, INDIRECT(""'"" & $B$16 & ""'!"&""" & $B$12 & "":"" & $B$12)))) ) ) / $D$6 ) "),0.0) -> 0 | J19: =IFERROR(__xludf.DUMMYFUNCTION("IF($D$7=0, 0, VAR.S( FILTER( INDIRECT(""'"" & $B$16 & ""'!"" & $B19 & "":"" & $B19), (INDIRECT(""'"" & $B$16 & ""'!"" & $B$17 & "":"" & $B$17) = J$18) * (ISNUMBER(SEARCH($B$4, INDIRECT(""'"" & $B$16 & ""'!"&""" & $B$12 & "":"" & $B$12)))) ) ) / $D$7 ) "),0.0) -> 0 | K19: =IFERROR(__xludf.DUMMYFUNCTION("IF($D$8=0, 0, VAR.S( FILTER( INDIRECT(""'"" & $B$16 & ""'!"" & $B19 & "":"" & $B19), (INDIRECT(""'"" & $B$16 & ""'!"" & $B$17 & "":"" & $B$17) = K$18) * (ISNUMBER(SEARCH($B$4, INDIRECT(""'"" & $B$16 & ""'!"&""" & $B$12 & "":"" & $B$12)))) ) ) / $D$8 ) "),0.0) -> 0 | L19: =IFERROR(__xludf.DUMMYFUNCTION("IF($D$9=0, 0, VAR.S( FILTER( INDIRECT(""'"" & $B$16 & ""'!"" & $B19 & "":"" & $B19), (INDIRECT(""'"" & $B$16 & ""'!"" & $B$17 & "":"" & $B$17) = L$18) * (ISNUMBER(SEARCH($B$4, INDIRECT(""'"" & $B$16 & ""'!"&""" & $B$12 & "":"" & $B$12)))) ) ) / $D$9 ) "),0.0) -> 0 | M19: =IFERROR(__xludf.DUMMYFUNCTION("IF($D$10=0, 0, VAR.S( FILTER( INDIRECT(""'"" & $B$16 & ""'!"" & $B19 & "":"" & $B19), (INDIRECT(""'"" & $B$16 & ""'!"" & $B$17 & "":"" & $B$17) = M$18) * (ISNUMBER(SEARCH($B$4, INDIRECT(""'"" & $B$16 & ""'!"&""" & $B$12 & "":"" & $B$12)))) ) ) / $D$10 ) "),0.0) -> 0 | N19: =IFERROR(__xludf.DUMMYFUNCTION("AVERAGE( FILTER( INDIRECT(""'"" & $B$16 & ""'!"" & $B19 & "":"" & $B19), (INDIRECT(""'"" & $B$16 & ""'!"" & $B$17 & "":"" & $B$17) = I$18) * (ISNUMBER(SEARCH($B$4, INDIRECT(""'"" & $B$16 & ""'!"" & $B$12 & "":"""&" & $B$12)))) ) )"),0.0) -> 0 | O19: =IFERROR(__xludf.DUMMYFUNCTION("AVERAGE( FILTER( INDIRECT(""'"" & $B$16 & ""'!"" & $B19 & "":"" & $B19), (INDIRECT(""'"" & $B$16 & ""'!"" & $B$17 & "":"" & $B$17) = J$18) * (ISNUMBER(SEARCH($B$4, INDIRECT(""'"" & $B$16 & ""'!"" & $B$12 & "":"""&" & $B$12)))) ) )"),"#N/A") -> #N/A | P19: =IFERROR(__xludf.DUMMYFUNCTION("AVERAGE( FILTER( INDIRECT(""'"" & $B$16 & ""'!"" & $B19 & "":"" & $B19), (INDIRECT(""'"" & $B$16 & ""'!"" & $B$17 & "":"" & $B$17) = K$18) * (ISNUMBER(SEARCH($B$4, INDIRECT(""'"" & $B$16 & ""'!"" & $B$12 & "":"""&" & $B$12)))) ) )"),"#N/A") -> #N/A | Q19: =IFERROR(__xludf.DUMMYFUNCTION("AVERAGE( FILTER( INDIRECT(""'"" & $B$16 & ""'!"" & $B19 & "":"" & $B19), (INDIRECT(""'"" & $B$16 & ""'!"" & $B$17 & "":"" & $B$17) = L$18) * (ISNUMBER(SEARCH($B$4, INDIRECT(""'"" & $B$16 & ""'!"" & $B$12 & "":"""&" & $B$12)))) ) )"),"#N/A") -> #N/A | R19: =IFERROR(__xludf.DUMMYFUNCTION("AVERAGE( FILTER( INDIRECT(""'"" & $B$16 & ""'!"" & $B19 & "":"" & $B19), (INDIRECT(""'"" & $B$16 & ""'!"" & $B$17 & "":"" & $B$17) = M$18) * (ISNUMBER(SEARCH($B$4, INDIRECT(""'"" & $B$16 & ""'!"" & $B$12 & "":"""&" & $B$12)))) ) )"),"#N/A") -> #N/A | S19: =($B$6^2*I19)^0.5 -> 0 | T19: =($B$7^2*J19)^0.5 -> 0 | U19: =($B$8^2*K19)^0.5 -> 0 | V19: =($B$9^2*L19)^0.5 -> 0 | W19: =($B$10^2*M19)^0.5 -> 0 | X19: =N19*$B$6 -> 0 | Y19: =O19*$B$7 -> #N/A | Z19: =P19*$B$8 -> #N/A | AA19: =Q19*$B$9 -> #N/A | AB19: =R19*$B$10 -> #N/A | AC19: =N19*$C$6 -> 0 | AD19: =O19*$C$7 -> #N/A | AE19: =P19*$C$8 -> #N/A | AF19: =Q19*$C$9 -> #N/A | AG19: =R19*$C$10 -> #N/A | AH19: =(S19*S19+T19*T19+U19*U19+V19*V19+W19*W19)^0.5 -> 0 | AI19: =AH19*$B$14 -> 0 | AJ19: =SUM(X19:AB19) -> #N/A | AK19: =IF(AI19=0,0,AI19/AJ19) -> 0 | AL19: =AJ19/$B$2 -> #N/A
A20: Def2017 | B20: =IFERROR("$" & SUBSTITUTE(ADDRESS(1, MATCH(A20, INDIRECT("'" & $B$16 & "'!1:1"), 0), 4), "1", ""), "Not Found") -> $AH | C20: =COUNTIFS(INDIRECT("'" & $B$16 & "'!" & $B$17 & ":" & $B$17),C$18,INDIRECT("'" & $B$16 & "'!" & $B$18 & ":" & $B$18),$A20,INDIRECT("'" & $B$16 & "'!" & $B$12 & ":" & $B$12), "*" & $B$4 & "*") -> 1 | D20: =COUNTIFS(INDIRECT("'" & $B$16 & "'!" & $B$17 & ":" & $B$17),D$18,INDIRECT("'" & $B$16 & "'!" & $B$18 & ":" & $B$18),$A20,INDIRECT("'" & $B$16 & "'!" & $B$12 & ":" & $B$12), "*" & $B$4 & "*") -> 0 | E20: =COUNTIFS(INDIRECT("'" & $B$16 & "'!" & $B$17 & ":" & $B$17),E$18,INDIRECT("'" & $B$16 & "'!" & $B$18 & ":" & $B$18),$A20,INDIRECT("'" & $B$16 & "'!" & $B$12 & ":" & $B$12), "*" & $B$4 & "*") -> 0 | F20: =COUNTIFS(INDIRECT("'" & $B$16 & "'!" & $B$17 & ":" & $B$17),F$18,INDIRECT("'" & $B$16 & "'!" & $B$18 & ":" & $B$18),$A20,INDIRECT("'" & $B$16 & "'!" & $B$12 & ":" & $B$12), "*" & $B$4 & "*") -> 0 | G20: =COUNTIFS(INDIRECT("'" & $B$16 & "'!" & $B$17 & ":" & $B$17),G$18,INDIRECT("'" & $B$16 & "'!" & $B$18 & ":" & $B$18),$A20,INDIRECT("'" & $B$16 & "'!" & $B$12 & ":" & $B$12), "*" & $B$4 & "*") -> 0 | H20: =SUM(C20:G20) -> 1 | I20: =IFERROR(__xludf.DUMMYFUNCTION("IF($D$6=0, 0, VAR.S( FILTER( INDIRECT(""'"" & $B$16 & ""'!"" & $B20 & "":"" & $B20), (INDIRECT(""'"" & $B$16 & ""'!"" & $B$17 & "":"" & $B$17) = I$18) * (ISNUMBER(SEARCH($B$4, INDIRECT(""'"" & $B$16 & ""'!"&""" & $B$12 & "":"" & $B$12)))) ) ) / $D$6 ) "),0.11111111111111112) -> 0.11111111 | J20: =IFERROR(__xludf.DUMMYFUNCTION("IF($D$7=0, 0, VAR.S( FILTER( INDIRECT(""'"" & $B$16 & ""'!"" & $B20 & "":"" & $B20), (INDIRECT(""'"" & $B$16 & ""'!"" & $B$17 & "":"" & $B$17) = J$18) * (ISNUMBER(SEARCH($B$4, INDIRECT(""'"" & $B$16 & ""'!"&""" & $B$12 & "":"" & $B$12)))) ) ) / $D$7 ) "),0.0) -> 0 | K20: =IFERROR(__xludf.DUMMYFUNCTION("IF($D$8=0, 0, VAR.S( FILTER( INDIRECT(""'"" & $B$16 & ""'!"" & $B20 & "":"" & $B20), (INDIRECT(""'"" & $B$16 & ""'!"" & $B$17 & "":"" & $B$17) = K$18) * (ISNUMBER(SEARCH($B$4, INDIRECT(""'"" & $B$16 & ""'!"&""" & $B$12 & "":"" & $B$12)))) ) ) / $D$8 ) "),0.0) -> 0 | L20: =IFERROR(__xludf.DUMMYFUNCTION("IF($D$9=0, 0, VAR.S( FILTER( INDIRECT(""'"" & $B$16 & ""'!"" & $B20 & "":"" & $B20), (INDIRECT(""'"" & $B$16 & ""'!"" & $B$17 & "":"" & $B$17) = L$18) * (ISNUMBER(SEARCH($B$4, INDIRECT(""'"" & $B$16 & ""'!"&""" & $B$12 & "":"" & $B$12)))) ) ) / $D$9 ) "),0.0) -> 0 | M20: =IFERROR(__xludf.DUMMYFUNCTION("IF($D$10=0, 0, VAR.S( FILTER( INDIRECT(""'"" & $B$16 & ""'!"" & $B20 & "":"" & $B20), (INDIRECT(""'"" & $B$16 & ""'!"" & $B$17 & "":"" & $B$17) = M$18) * (ISNUMBER(SEARCH($B$4, INDIRECT(""'"" & $B$16 & ""'!"&""" & $B$12 & "":"" & $B$12)))) ) ) / $D$10 ) "),0.0) -> 0 | N20: =IFERROR(__xludf.DUMMYFUNCTION("AVERAGE( FILTER( INDIRECT(""'"" & $B$16 & ""'!"" & $B20 & "":"" & $B20), (INDIRECT(""'"" & $B$16 & ""'!"" & $B$17 & "":"" & $B$17) = I$18) * (ISNUMBER(SEARCH($B$4, INDIRECT(""'"" & $B$16 & ""'!"" & $B$12 & "":"""&" & $B$12)))) ) )"),0.3333333333333333) -> 0.33333333 | O20: =IFERROR(__xludf.DUMMYFUNCTION("AVERAGE( FILTER( INDIRECT(""'"" & $B$16 & ""'!"" & $B20 & "":"" & $B20), (INDIRECT(""'"" & $B$16 & ""'!"" & $B$17 & "":"" & $B$17) = J$18) * (ISNUMBER(SEARCH($B$4, INDIRECT(""'"" & $B$16 & ""'!"" & $B$12 & "":"""&" & $B$12)))) ) )"),"#N/A") -> #N/A | P20: =IFERROR(__xludf.DUMMYFUNCTION("AVERAGE( FILTER( INDIRECT(""'"" & $B$16 & ""'!"" & $B20 & "":"" & $B20), (INDIRECT(""'"" & $B$16 & ""'!"" & $B$17 & "":"" & $B$17) = K$18) * (ISNUMBER(SEARCH($B$4, INDIRECT(""'"" & $B$16 & ""'!"" & $B$12 & "":"""&" & $B$12)))) ) )"),"#N/A") -> #N/A | Q20: =IFERROR(__xludf.DUMMYFUNCTION("AVERAGE( FILTER( INDIRECT(""'"" & $B$16 & ""'!"" & $B20 & "":"" & $B20), (INDIRECT(""'"" & $B$16 & ""'!"" & $B$17 & "":"" & $B$17) = L$18) * (ISNUMBER(SEARCH($B$4, INDIRECT(""'"" & $B$16 & ""'!"" & $B$12 & "":"""&" & $B$12)))) ) )"),"#N/A") -> #N/A | R20: =IFERROR(__xludf.DUMMYFUNCTION("AVERAGE( FILTER( INDIRECT(""'"" & $B$16 & ""'!"" & $B20 & "":"" & $B20), (INDIRECT(""'"" & $B$16 & ""'!"" & $B$17 & "":"" & $B$17) = M$18) * (ISNUMBER(SEARCH($B$4, INDIRECT(""'"" & $B$16 & ""'!"" & $B$12 & "":"""&" & $B$12)))) ) )"),"#N/A") -> #N/A | S20: =($B$6^2*I20)^0.5 -> 16705569 | T20: =($B$7^2*J20)^0.5 -> 0 | U20: =($B$8^2*K20)^0.5 -> 0 | V20: =($B$9^2*L20)^0.5 -> 0 | W20: =($B$10^2*M20)^0.5 -> 0 | X20: =N20*$B$6 -> 16705569 | Y20: =O20*$B$7 -> #N/A | Z20: =P20*$B$8 -> #N/A | AA20: =Q20*$B$9 -> #N/A | AB20: =R20*$B$10 -> #N/A | AC20: =N20*$C$6 -> 0.27029245 | AD20: =O20*$C$7 -> #N/A | AE20: =P20*$C$8 -> #N/A | AF20: =Q20*$C$9 -> #N/A | AG20: =R20*$C$10 -> #N/A | AH20: =(S20*S20+T20*T20+U20*U20+V20*V20+W20*W20)^0.5 -> 16705569 | AI20: =AH20*$B$14 -> 27480662 | AJ20: =SUM(X20:AB20) -> #N/A | AK20: =IF(AI20=0,0,AI20/AJ20) -> #N/A | AL20: =AJ20/$B$2 -> #N/A
A21: Def2018 | B21: =IFERROR("$" & SUBSTITUTE(ADDRESS(1, MATCH(A21, INDIRECT("'" & $B$16 & "'!1:1"), 0), 4), "1", ""), "Not Found") -> $AI | C21: =COUNTIFS(INDIRECT("'" & $B$16 & "'!" & $B$17 & ":" & $B$17),C$18,INDIRECT("'" & $B$16 & "'!" & $B$18 & ":" & $B$18),$A21,INDIRECT("'" & $B$16 & "'!" & $B$12 & ":" & $B$12), "*" & $B$4 & "*") -> 0 | D21: =COUNTIFS(INDIRECT("'" & $B$16 & "'!" & $B$17 & ":" & $B$17),D$18,INDIRECT("'" & $B$16 & "'!" & $B$18 & ":" & $B$18),$A21,INDIRECT("'" & $B$16 & "'!" & $B$12 & ":" & $B$12), "*" & $B$4 & "*") -> 0 | E21: =COUNTIFS(INDIRECT("'" & $B$16 & "'!" & $B$17 & ":" & $B$17),E$18,INDIRECT("'" & $B$16 & "'!" & $B$18 & ":" & $B$18),$A21,INDIRECT("'" & $B$16 & "'!" & $B$12 & ":" & $B$12), "*" & $B$4 & "*") -> 0 | F21: =COUNTIFS(INDIRECT("'" & $B$16 & "'!" & $B$17 & ":" & $B$17),F$18,INDIRECT("'" & $B$16 & "'!" & $B$18 & ":" & $B$18),$A21,INDIRECT("'" & $B$16 & "'!" & $B$12 & ":" & $B$12), "*" & $B$4 & "*") -> 0 | G21: =COUNTIFS(INDIRECT("'" & $B$16 & "'!" & $B$17 & ":" & $B$17),G$18,INDIRECT("'" & $B$16 & "'!" & $B$18 & ":" & $B$18),$A21,INDIRECT("'" & $B$16 & "'!" & $B$12 & ":" & $B$12), "*" & $B$4 & "*") -> 0 | H21: =SUM(C21:G21) -> 0 | I21: =IFERROR(__xludf.DUMMYFUNCTION("IF($D$6=0, 0, VAR.S( FILTER( INDIRECT(""'"" & $B$16 & ""'!"" & $B21 & "":"" & $B21), (INDIRECT(""'"" & $B$16 & ""'!"" & $B$17 & "":"" & $B$17) = I$18) * (ISNUMBER(SEARCH($B$4, INDIRECT(""'"" & $B$16 & ""'!"&""" & $B$12 & "":"" & $B$12)))) ) ) / $D$6 ) "),0.0) -> 0 | J21: =IFERROR(__xludf.DUMMYFUNCTION("IF($D$7=0, 0, VAR.S( FILTER( INDIRECT(""'"" & $B$16 & ""'!"" & $B21 & "":"" & $B21), (INDIRECT(""'"" & $B$16 & ""'!"" & $B$17 & "":"" & $B$17) = J$18) * (ISNUMBER(SEARCH($B$4, INDIRECT(""'"" & $B$16 & ""'!"&""" & $B$12 & "":"" & $B$12)))) ) ) / $D$7 ) "),0.0) -> 0 | K21: =IFERROR(__xludf.DUMMYFUNCTION("IF($D$8=0, 0, VAR.S( FILTER( INDIRECT(""'"" & $B$16 & ""'!"" & $B21 & "":"" & $B21), (INDIRECT(""'"" & $B$16 & ""'!"" & $B$17 & "":"" & $B$17) = K$18) * (ISNUMBER(SEARCH($B$4, INDIRECT(""'"" & $B$16 & ""'!"&""" & $B$12 & "":"" & $B$12)))) ) ) / $D$8 ) "),0.0) -> 0 | L21: =IFERROR(__xludf.DUMMYFUNCTION("IF($D$9=0, 0, VAR.S( FILTER( INDIRECT(""'"" & $B$16 & ""'!"" & $B21 & "":"" & $B21), (INDIRECT(""'"" & $B$16 & ""'!"" & $B$17 & "":"" & $B$17) = L$18) * (ISNUMBER(SEARCH($B$4, INDIRECT(""'"" & $B$16 & ""'!"&""" & $B$12 & "":"" & $B$12)))) ) ) / $D$9 ) "),0.0) -> 0 | M21: =IFERROR(__xludf.DUMMYFUNCTION("IF($D$10=0, 0, VAR.S( FILTER( INDIRECT(""'"" & $B$16 & ""'!"" & $B21 & "":"" & $B21), (INDIRECT(""'"" & $B$16 & ""'!"" & $B$17 & "":"" & $B$17) = M$18) * (ISNUMBER(SEARCH($B$4, INDIRECT(""'"" & $B$16 & ""'!"&""" & $B$12 & "":"" & $B$12)))) ) ) / $D$10 ) "),0.0) -> 0 | N21: =IFERROR(__xludf.DUMMYFUNCTION("AVERAGE( FILTER( INDIRECT(""'"" & $B$16 & ""'!"" & $B21 & "":"" & $B21), (INDIRECT(""'"" & $B$16 & ""'!"" & $B$17 & "":"" & $B$17) = I$18) * (ISNUMBER(SEARCH($B$4, INDIRECT(""'"" & $B$16 & ""'!"" & $B$12 & "":"""&" & $B$12)))) ) )"),0.0) -> 0 | O21: =IFERROR(__xludf.DUMMYFUNCTION("AVERAGE( FILTER( INDIRECT(""'"" & $B$16 & ""'!"" & $B21 & "":"" & $B21), (INDIRECT(""'"" & $B$16 & ""'!"" & $B$17 & "":"" & $B$17) = J$18) * (ISNUMBER(SEARCH($B$4, INDIRECT(""'"" & $B$16 & ""'!"" & $B$12 & "":"""&" & $B$12)))) ) )"),"#N/A") -> #N/A | P21: =IFERROR(__xludf.DUMMYFUNCTION("AVERAGE( FILTER( INDIRECT(""'"" & $B$16 & ""'!"" & $B21 & "":"" & $B21), (INDIRECT(""'"" & $B$16 & ""'!"" & $B$17 & "":"" & $B$17) = K$18) * (ISNUMBER(SEARCH($B$4, INDIRECT(""'"" & $B$16 & ""'!"" & $B$12 & "":"""&" & $B$12)))) ) )"),"#N/A") -> #N/A | Q21: =IFERROR(__xludf.DUMMYFUNCTION("AVERAGE( FILTER( INDIRECT(""'"" & $B$16 & ""'!"" & $B21 & "":"" & $B21), (INDIRECT(""'"" & $B$16 & ""'!"" & $B$17 & "":"" & $B$17) = L$18) * (ISNUMBER(SEARCH($B$4, INDIRECT(""'"" & $B$16 & ""'!"" & $B$12 & "":"""&" & $B$12)))) ) )"),"#N/A") -> #N/A | R21: =IFERROR(__xludf.DUMMYFUNCTION("AVERAGE( FILTER( INDIRECT(""'"" & $B$16 & ""'!"" & $B21 & "":"" & $B21), (INDIRECT(""'"" & $B$16 & ""'!"" & $B$17 & "":"" & $B$17) = M$18) * (ISNUMBER(SEARCH($B$4, INDIRECT(""'"" & $B$16 & ""'!"" & $B$12 & "":"""&" & $B$12)))) ) )"),"#N/A") -> #N/A | S21: =($B$6^2*I21)^0.5 -> 0 | T21: =($B$7^2*J21)^0.5 -> 0 | U21: =($B$8^2*K21)^0.5 -> 0 | V21: =($B$9^2*L21)^0.5 -> 0 | W21: =($B$10^2*M21)^0.5 -> 0 | X21: =N21*$B$6 -> 0 | Y21: =O21*$B$7 -> #N/A | Z21: =P21*$B$8 -> #N/A | AA21: =Q21*$B$9 -> #N/A | AB21: =R21*$B$10 -> #N/A | AC21: =N21*$C$6 -> 0 | AD21: =O21*$C$7 -> #N/A | AE21: =P21*$C$8 -> #N/A | AF21: =Q21*$C$9 -> #N/A | AG21: =R21*$C$10 -> #N/A | AH21: =(S21*S21+T21*T21+U21*U21+V21*V21+W21*W21)^0.5 -> 0 | AI21: =AH21*$B$14 -> 0 | AJ21: =SUM(X21:AB21) -> #N/A | AK21: =IF(AI21=0,0,AI21/AJ21) -> 0 | AL21: =AJ21/$B$2 -> #N/A
A22: Def2019 | B22: =IFERROR("$" & SUBSTITUTE(ADDRESS(1, MATCH(A22, INDIRECT("'" & $B$16 & "'!1:1"), 0), 4), "1", ""), "Not Found") -> $AJ | C22: =COUNTIFS(INDIRECT("'" & $B$16 & "'!" & $B$17 & ":" & $B$17),C$18,INDIRECT("'" & $B$16 & "'!" & $B$18 & ":" & $B$18),$A22,INDIRECT("'" & $B$16 & "'!" & $B$12 & ":" & $B$12), "*" & $B$4 & "*") -> 0 | D22: =COUNTIFS(INDIRECT("'" & $B$16 & "'!" & $B$17 & ":" & $B$17),D$18,INDIRECT("'" & $B$16 & "'!" & $B$18 & ":" & $B$18),$A22,INDIRECT("'" & $B$16 & "'!" & $B$12 & ":" & $B$12), "*" & $B$4 & "*") -> 0 | E22: =COUNTIFS(INDIRECT("'" & $B$16 & "'!" & $B$17 & ":" & $B$17),E$18,INDIRECT("'" & $B$16 & "'!" & $B$18 & ":" & $B$18),$A22,INDIRECT("'" & $B$16 & "'!" & $B$12 & ":" & $B$12), "*" & $B$4 & "*") -> 0 | F22: =COUNTIFS(INDIRECT("'" & $B$16 & "'!" & $B$17 & ":" & $B$17),F$18,INDIRECT("'" & $B$16 & "'!" & $B$18 & ":" & $B$18),$A22,INDIRECT("'" & $B$16 & "'!" & $B$12 & ":" & $B$12), "*" & $B$4 & "*") -> 0 | G22: =COUNTIFS(INDIRECT("'" & $B$16 & "'!" & $B$17 & ":" & $B$17),G$18,INDIRECT("'" & $B$16 & "'!" & $B$18 & ":" & $B$18),$A22,INDIRECT("'" & $B$16 & "'!" & $B$12 & ":" & $B$12), "*" & $B$4 & "*") -> 0 | H22: =SUM(C22:G22) -> 0 | I22: =IFERROR(__xludf.DUMMYFUNCTION("IF($D$6=0, 0, VAR.S( FILTER( INDIRECT(""'"" & $B$16 & ""'!"" & $B22 & "":"" & $B22), (INDIRECT(""'"" & $B$16 & ""'!"" & $B$17 & "":"" & $B$17) = I$18) * (ISNUMBER(SEARCH($B$4, INDIRECT(""'"" & $B$16 & ""'!"&""" & $B$12 & "":"" & $B$12)))) ) ) / $D$6 ) "),0.0) -> 0 | J22: =IFERROR(__xludf.DUMMYFUNCTION("IF($D$7=0, 0, VAR.S( FILTER( INDIRECT(""'"" & $B$16 & ""'!"" & $B22 & "":"" & $B22), (INDIRECT(""'"" & $B$16 & ""'!"" & $B$17 & "":"" & $B$17) = J$18) * (ISNUMBER(SEARCH($B$4, INDIRECT(""'"" & $B$16 & ""'!"&""" & $B$12 & "":"" & $B$12)))) ) ) / $D$7 ) "),0.0) -> 0 | K22: =IFERROR(__xludf.DUMMYFUNCTION("IF($D$8=0, 0, VAR.S( FILTER( INDIRECT(""'"" & $B$16 & ""'!"" & $B22 & "":"" & $B22), (INDIRECT(""'"" & $B$16 & ""'!"" & $B$17 & "":"" & $B$17) = K$18) * (ISNUMBER(SEARCH($B$4, INDIRECT(""'"" & $B$16 & ""'!"&""" & $B$12 & "":"" & $B$12)))) ) ) / $D$8 ) "),0.0) -> 0 | L22: =IFERROR(__xludf.DUMMYFUNCTION("IF($D$9=0, 0, VAR.S( FILTER( INDIRECT(""'"" & $B$16 & ""'!"" & $B22 & "":"" & $B22), (INDIRECT(""'"" & $B$16 & ""'!"" & $B$17 & "":"" & $B$17) = L$18) * (ISNUMBER(SEARCH($B$4, INDIRECT(""'"" & $B$16 & ""'!"&""" & $B$12 & "":"" & $B$12)))) ) ) / $D$9 ) "),0.0) -> 0 | M22: =IFERROR(__xludf.DUMMYFUNCTION("IF($D$10=0, 0, VAR.S( FILTER( INDIRECT(""'"" & $B$16 & ""'!"" & $B22 & "":"" & $B22), (INDIRECT(""'"" & $B$16 & ""'!"" & $B$17 & "":"" & $B$17) = M$18) * (ISNUMBER(SEARCH($B$4, INDIRECT(""'"" & $B$16 & ""'!"&""" & $B$12 & "":"" & $B$12)))) ) ) / $D$10 ) "),0.0) -> 0 | N22: =IFERROR(__xludf.DUMMYFUNCTION("AVERAGE( FILTER( INDIRECT(""'"" & $B$16 & ""'!"" & $B22 & "":"" & $B22), (INDIRECT(""'"" & $B$16 & ""'!"" & $B$17 & "":"" & $B$17) = I$18) * (ISNUMBER(SEARCH($B$4, INDIRECT(""'"" & $B$16 & ""'!"" & $B$12 & "":"""&" & $B$12)))) ) )"),0.0) -> 0 | O22: =IFERROR(__xludf.DUMMYFUNCTION("AVERAGE( FILTER( INDIRECT(""'"" & $B$16 & ""'!"" & $B22 & "":"" & $B22), (INDIRECT(""'"" & $B$16 & ""'!"" & $B$17 & "":"" & $B$17) = J$18) * (ISNUMBER(SEARCH($B$4, INDIRECT(""'"" & $B$16 & ""'!"" & $B$12 & "":"""&" & $B$12)))) ) )"),"#N/A") -> #N/A | P22: =IFERROR(__xludf.DUMMYFUNCTION("AVERAGE( FILTER( INDIRECT(""'"" & $B$16 & ""'!"" & $B22 & "":"" & $B22), (INDIRECT(""'"" & $B$16 & ""'!"" & $B$17 & "":"" & $B$17) = K$18) * (ISNUMBER(SEARCH($B$4, INDIRECT(""'"" & $B$16 & ""'!"" & $B$12 & "":"""&" & $B$12)))) ) )"),"#N/A") -> #N/A | Q22: =IFERROR(__xludf.DUMMYFUNCTION("AVERAGE( FILTER( INDIRECT(""'"" & $B$16 & ""'!"" & $B22 & "":"" & $B22), (INDIRECT(""'"" & $B$16 & ""'!"" & $B$17 & "":"" & $B$17) = L$18) * (ISNUMBER(SEARCH($B$4, INDIRECT(""'"" & $B$16 & ""'!"" & $B$12 & "":"""&" & $B$12)))) ) )"),"#N/A") -> #N/A | R22: =IFERROR(__xludf.DUMMYFUNCTION("AVERAGE( FILTER( INDIRECT(""'"" & $B$16 & ""'!"" & $B22 & "":"" & $B22), (INDIRECT(""'"" & $B$16 & ""'!"" & $B$17 & "":"" & $B$17) = M$18) * (ISNUMBER(SEARCH($B$4, INDIRECT(""'"" & $B$16 & ""'!"" & $B$12 & "":"""&" & $B$12)))) ) )"),"#N/A") -> #N/A | S22: =($B$6^2*I22)^0.5 -> 0 | T22: =($B$7^2*J22)^0.5 -> 0 | U22: =($B$8^2*K22)^0.5 -> 0 | V22: =($B$9^2*L22)^0.5 -> 0 | W22: =($B$10^2*M22)^0.5 -> 0 | X22: =N22*$B$6 -> 0 | Y22: =O22*$B$7 -> #N/A | Z22: =P22*$B$8 -> #N/A | AA22: =Q22*$B$9 -> #N/A | AB22: =R22*$B$10 -> #N/A | AC22: =N22*$C$6 -> 0 | AD22: =O22*$C$7 -> #N/A | AE22: =P22*$C$8 -> #N/A | AF22: =Q22*$C$9 -> #N/A | AG22: =R22*$C$10 -> #N/A | AH22: =(S22*S22+T22*T22+U22*U22+V22*V22+W22*W22)^0.5 -> 0 | AI22: =AH22*$B$14 -> 0 | AJ22: =SUM(X22:AB22) -> #N/A | AK22: =IF(AI22=0,0,AI22/AJ22) -> 0 | AL22: =AJ22/$B$2 -> #N/A
A23: Def2020 | B23: =IFERROR("$" & SUBSTITUTE(ADDRESS(1, MATCH(A23, INDIRECT("'" & $B$16 & "'!1:1"), 0), 4), "1", ""), "Not Found") -> $AK | C23: =COUNTIFS(INDIRECT("'" & $B$16 & "'!" & $B$17 & ":" & $B$17),C$18,INDIRECT("'" & $B$16 & "'!" & $B$18 & ":" & $B$18),$A23,INDIRECT("'" & $B$16 & "'!" & $B$12 & ":" & $B$12), "*" & $B$4 & "*") -> 0 | D23: =COUNTIFS(INDIRECT("'" & $B$16 & "'!" & $B$17 & ":" & $B$17),D$18,INDIRECT("'" & $B$16 & "'!" & $B$18 & ":" & $B$18),$A23,INDIRECT("'" & $B$16 & "'!" & $B$12 & ":" & $B$12), "*" & $B$4 & "*") -> 0 | E23: =COUNTIFS(INDIRECT("'" & $B$16 & "'!" & $B$17 & ":" & $B$17),E$18,INDIRECT("'" & $B$16 & "'!" & $B$18 & ":" & $B$18),$A23,INDIRECT("'" & $B$16 & "'!" & $B$12 & ":" & $B$12), "*" & $B$4 & "*") -> 0 | F23: =COUNTIFS(INDIRECT("'" & $B$16 & "'!" & $B$17 & ":" & $B$17),F$18,INDIRECT("'" & $B$16 & "'!" & $B$18 & ":" & $B$18),$A23,INDIRECT("'" & $B$16 & "'!" & $B$12 & ":" & $B$12), "*" & $B$4 & "*") -> 0 | G23: =COUNTIFS(INDIRECT("'" & $B$16 & "'!" & $B$17 & ":" & $B$17),G$18,INDIRECT("'" & $B$16 & "'!" & $B$18 & ":" & $B$18),$A23,INDIRECT("'" & $B$16 & "'!" & $B$12 & ":" & $B$12), "*" & $B$4 & "*") -> 0 | H23: =SUM(C23:G23) -> 0 | I23: =IFERROR(__xludf.DUMMYFUNCTION("IF($D$6=0, 0, VAR.S( FILTER( INDIRECT(""'"" & $B$16 & ""'!"" & $B23 & "":"" & $B23), (INDIRECT(""'"" & $B$16 & ""'!"" & $B$17 & "":"" & $B$17) = I$18) * (ISNUMBER(SEARCH($B$4, INDIRECT(""'"" & $B$16 & ""'!"&""" & $B$12 & "":"" & $B$12)))) ) ) / $D$6 ) "),0.0) -> 0 | J23: =IFERROR(__xludf.DUMMYFUNCTION("IF($D$7=0, 0, VAR.S( FILTER( INDIRECT(""'"" & $B$16 & ""'!"" & $B23 & "":"" & $B23), (INDIRECT(""'"" & $B$16 & ""'!"" & $B$17 & "":"" & $B$17) = J$18) * (ISNUMBER(SEARCH($B$4, INDIRECT(""'"" & $B$16 & ""'!"&""" & $B$12 & "":"" & $B$12)))) ) ) / $D$7 ) "),0.0) -> 0 | K23: =IFERROR(__xludf.DUMMYFUNCTION("IF($D$8=0, 0, VAR.S( FILTER( INDIRECT(""'"" & $B$16 & ""'!"" & $B23 & "":"" & $B23), (INDIRECT(""'"" & $B$16 & ""'!"" & $B$17 & "":"" & $B$17) = K$18) * (ISNUMBER(SEARCH($B$4, INDIRECT(""'"" & $B$16 & ""'!"&""" & $B$12 & "":"" & $B$12)))) ) ) / $D$8 ) "),0.0) -> 0 | L23: =IFERROR(__xludf.DUMMYFUNCTION("IF($D$9=0, 0, VAR.S( FILTER( INDIRECT(""'"" & $B$16 & ""'!"" & $B23 & "":"" & $B23), (INDIRECT(""'"" & $B$16 & ""'!"" & $B$17 & "":"" & $B$17) = L$18) * (ISNUMBER(SEARCH($B$4, INDIRECT(""'"" & $B$16 & ""'!"&""" & $B$12 & "":"" & $B$12)))) ) ) / $D$9 ) "),0.0) -> 0 | M23: =IFERROR(__xludf.DUMMYFUNCTION("IF($D$10=0, 0, VAR.S( FILTER( INDIRECT(""'"" & $B$16 & ""'!"" & $B23 & "":"" & $B23), (INDIRECT(""'"" & $B$16 & ""'!"" & $B$17 & "":"" & $B$17) = M$18) * (ISNUMBER(SEARCH($B$4, INDIRECT(""'"" & $B$16 & ""'!"&""" & $B$12 & "":"" & $B$12)))) ) ) / $D$10 ) "),0.0) -> 0 | N23: =IFERROR(__xludf.DUMMYFUNCTION("AVERAGE( FILTER( INDIRECT(""'"" & $B$16 & ""'!"" & $B23 & "":"" & $B23), (INDIRECT(""'"" & $B$16 & ""'!"" & $B$17 & "":"" & $B$17) = I$18) * (ISNUMBER(SEARCH($B$4, INDIRECT(""'"" & $B$16 & ""'!"" & $B$12 & "":"""&" & $B$12)))) ) )"),0.0) -> 0 | O23: =IFERROR(__xludf.DUMMYFUNCTION("AVERAGE( FILTER( INDIRECT(""'"" & $B$16 & ""'!"" & $B23 & "":"" & $B23), (INDIRECT(""'"" & $B$16 & ""'!"" & $B$17 & "":"" & $B$17) = J$18) * (ISNUMBER(SEARCH($B$4, INDIRECT(""'"" & $B$16 & ""'!"" & $B$12 & "":"""&" & $B$12)))) ) )"),"#N/A") -> #N/A | P23: =IFERROR(__xludf.DUMMYFUNCTION("AVERAGE( FILTER( INDIRECT(""'"" & $B$16 & ""'!"" & $B23 & "":"" & $B23), (INDIRECT(""'"" & $B$16 & ""'!"" & $B$17 & "":"" & $B$17) = K$18) * (ISNUMBER(SEARCH($B$4, INDIRECT(""'"" & $B$16 & ""'!"" & $B$12 & "":"""&" & $B$12)))) ) )"),"#N/A") -> #N/A | Q23: =IFERROR(__xludf.DUMMYFUNCTION("AVERAGE( FILTER( INDIRECT(""'"" & $B$16 & ""'!"" & $B23 & "":"" & $B23), (INDIRECT(""'"" & $B$16 & ""'!"" & $B$17 & "":"" & $B$17) = L$18) * (ISNUMBER(SEARCH($B$4, INDIRECT(""'"" & $B$16 & ""'!"" & $B$12 & "":"""&" & $B$12)))) ) )"),"#N/A") -> #N/A | R23: =IFERROR(__xludf.DUMMYFUNCTION("AVERAGE( FILTER( INDIRECT(""'"" & $B$16 & ""'!"" & $B23 & "":"" & $B23), (INDIRECT(""'"" & $B$16 & ""'!"" & $B$17 & "":"" & $B$17) = M$18) * (ISNUMBER(SEARCH($B$4, INDIRECT(""'"" & $B$16 & ""'!"" & $B$12 & "":"""&" & $B$12)))) ) )"),"#N/A") -> #N/A | S23: =($B$6^2*I23)^0.5 -> 0 | T23: =($B$7^2*J23)^0.5 -> 0 | U23: =($B$8^2*K23)^0.5 -> 0 | V23: =($B$9^2*L23)^0.5 -> 0 | W23: =($B$10^2*M23)^0.5 -> 0 | X23: =N23*$B$6 -> 0 | Y23: =O23*$B$7 -> #N/A | Z23: =P23*$B$8 -> #N/A | AA23: =Q23*$B$9 -> #N/A | AB23: =R23*$B$10 -> #N/A | AC23: =N23*$C$6 -> 0 | AD23: =O23*$C$7 -> #N/A | AE23: =P23*$C$8 -> #N/A | AF23: =Q23*$C$9 -> #N/A | AG23: =R23*$C$10 -> #N/A | AH23: =(S23*S23+T23*T23+U23*U23+V23*V23+W23*W23)^0.5 -> 0 | AI23: =AH23*$B$14 -> 0 | AJ23: =SUM(X23:AB23) -> #N/A | AK23: =IF(AI23=0,0,AI23/AJ23) -> 0 | AL23: =AJ23/$B$2 -> #N/A
A24: Def2021 | B24: =IFERROR("$" & SUBSTITUTE(ADDRESS(1, MATCH(A24, INDIRECT("'" & $B$16 & "'!1:1"), 0), 4), "1", ""), "Not Found") -> $AL | C24: =COUNTIFS(INDIRECT("'" & $B$16 & "'!" & $B$17 & ":" & $B$17),C$18,INDIRECT("'" & $B$16 & "'!" & $B$18 & ":" & $B$18),$A24,INDIRECT("'" & $B$16 & "'!" & $B$12 & ":" & $B$12), "*" & $B$4 & "*") -> 0 | D24: =COUNTIFS(INDIRECT("'" & $B$16 & "'!" & $B$17 & ":" & $B$17),D$18,INDIRECT("'" & $B$16 & "'!" & $B$18 & ":" & $B$18),$A24,INDIRECT("'" & $B$16 & "'!" & $B$12 & ":" & $B$12), "*" & $B$4 & "*") -> 0 | E24: =COUNTIFS(INDIRECT("'" & $B$16 & "'!" & $B$17 & ":" & $B$17),E$18,INDIRECT("'" & $B$16 & "'!" & $B$18 & ":" & $B$18),$A24,INDIRECT("'" & $B$16 & "'!" & $B$12 & ":" & $B$12), "*" & $B$4 & "*") -> 0 | F24: =COUNTIFS(INDIRECT("'" & $B$16 & "'!" & $B$17 & ":" & $B$17),F$18,INDIRECT("'" & $B$16 & "'!" & $B$18 & ":" & $B$18),$A24,INDIRECT("'" & $B$16 & "'!" & $B$12 & ":" & $B$12), "*" & $B$4 & "*") -> 0 | G24: =COUNTIFS(INDIRECT("'" & $B$16 & "'!" & $B$17 & ":" & $B$17),G$18,INDIRECT("'" & $B$16 & "'!" & $B$18 & ":" & $B$18),$A24,INDIRECT("'" & $B$16 & "'!" & $B$12 & ":" & $B$12), "*" & $B$4 & "*") -> 0 | H24: =SUM(C24:G24) -> 0 | I24: =IFERROR(__xludf.DUMMYFUNCTION("IF($D$6=0, 0, VAR.S( FILTER( INDIRECT(""'"" & $B$16 & ""'!"" & $B24 & "":"" & $B24), (INDIRECT(""'"" & $B$16 & ""'!"" & $B$17 & "":"" & $B$17) = I$18) * (ISNUMBER(SEARCH($B$4, INDIRECT(""'"" & $B$16 & ""'!"&""" & $B$12 & "":"" & $B$12)))) ) ) / $D$6 ) "),0.0) -> 0 | J24: =IFERROR(__xludf.DUMMYFUNCTION("IF($D$7=0, 0, VAR.S( FILTER( INDIRECT(""'"" & $B$16 & ""'!"" & $B24 & "":"" & $B24), (INDIRECT(""'"" & $B$16 & ""'!"" & $B$17 & "":"" & $B$17) = J$18) * (ISNUMBER(SEARCH($B$4, INDIRECT(""'"" & $B$16 & ""'!"&""" & $B$12 & "":"" & $B$12)))) ) ) / $D$7 ) "),0.0) -> 0 | K24: =IFERROR(__xludf.DUMMYFUNCTION("IF($D$8=0, 0, VAR.S( FILTER( INDIRECT(""'"" & $B$16 & ""'!"" & $B24 & "":"" & $B24), (INDIRECT(""'"" & $B$16 & ""'!"" & $B$17 & "":"" & $B$17) = K$18) * (ISNUMBER(SEARCH($B$4, INDIRECT(""'"" & $B$16 & ""'!"&""" & $B$12 & "":"" & $B$12)))) ) ) / $D$8 ) "),0.0) -> 0 | L24: =IFERROR(__xludf.DUMMYFUNCTION("IF($D$9=0, 0, VAR.S( FILTER( INDIRECT(""'"" & $B$16 & ""'!"" & $B24 & "":"" & $B24), (INDIRECT(""'"" & $B$16 & ""'!"" & $B$17 & "":"" & $B$17) = L$18) * (ISNUMBER(SEARCH($B$4, INDIRECT(""'"" & $B$16 & ""'!"&""" & $B$12 & "":"" & $B$12)))) ) ) / $D$9 ) "),0.0) -> 0 | M24: =IFERROR(__xludf.DUMMYFUNCTION("IF($D$10=0, 0, VAR.S( FILTER( INDIRECT(""'"" & $B$16 & ""'!"" & $B24 & "":"" & $B24), (INDIRECT(""'"" & $B$16 & ""'!"" & $B$17 & "":"" & $B$17) = M$18) * (ISNUMBER(SEARCH($B$4, INDIRECT(""'"" & $B$16 & ""'!"&""" & $B$12 & "":"" & $B$12)))) ) ) / $D$10 ) "),0.0) -> 0 | N24: =IFERROR(__xludf.DUMMYFUNCTION("AVERAGE( FILTER( INDIRECT(""'"" & $B$16 & ""'!"" & $B24 & "":"" & $B24), (INDIRECT(""'"" & $B$16 & ""'!"" & $B$17 & "":"" & $B$17) = I$18) * (ISNUMBER(SEARCH($B$4, INDIRECT(""'"" & $B$16 & ""'!"" & $B$12 & "":"""&" & $B$12)))) ) )"),0.0) -> 0 | O24: =IFERROR(__xludf.DUMMYFUNCTION("AVERAGE( FILTER( INDIRECT(""'"" & $B$16 & ""'!"" & $B24 & "":"" & $B24), (INDIRECT(""'"" & $B$16 & ""'!"" & $B$17 & "":"" & $B$17) = J$18) * (ISNUMBER(SEARCH($B$4, INDIRECT(""'"" & $B$16 & ""'!"" & $B$12 & "":"""&" & $B$12)))) ) )"),"#N/A") -> #N/A | P24: =IFERROR(__xludf.DUMMYFUNCTION("AVERAGE( FILTER( INDIRECT(""'"" & $B$16 & ""'!"" & $B24 & "":"" & $B24), (INDIRECT(""'"" & $B$16 & ""'!"" & $B$17 & "":"" & $B$17) = K$18) * (ISNUMBER(SEARCH($B$4, INDIRECT(""'"" & $B$16 & ""'!"" & $B$12 & "":"""&" & $B$12)))) ) )"),"#N/A") -> #N/A | Q24: =IFERROR(__xludf.DUMMYFUNCTION("AVERAGE( FILTER( INDIRECT(""'"" & $B$16 & ""'!"" & $B24 & "":"" & $B24), (INDIRECT(""'"" & $B$16 & ""'!"" & $B$17 & "":"" & $B$17) = L$18) * (ISNUMBER(SEARCH($B$4, INDIRECT(""'"" & $B$16 & ""'!"" & $B$12 & "":"""&" & $B$12)))) ) )"),"#N/A") -> #N/A | R24: =IFERROR(__xludf.DUMMYFUNCTION("AVERAGE( FILTER( INDIRECT(""'"" & $B$16 & ""'!"" & $B24 & "":"" & $B24), (INDIRECT(""'"" & $B$16 & ""'!"" & $B$17 & "":"" & $B$17) = M$18) * (ISNUMBER(SEARCH($B$4, INDIRECT(""'"" & $B$16 & ""'!"" & $B$12 & "":"""&" & $B$12)))) ) )"),"#N/A") -> #N/A | S24: =($B$6^2*I24)^0.5 -> 0 | T24: =($B$7^2*J24)^0.5 -> 0 | U24: =($B$8^2*K24)^0.5 -> 0 | V24: =($B$9^2*L24)^0.5 -> 0 | W24: =($B$10^2*M24)^0.5 -> 0 | X24: =N24*$B$6 -> 0 | Y24: =O24*$B$7 -> #N/A | Z24: =P24*$B$8 -> #N/A | AA24: =Q24*$B$9 -> #N/A | AB24: =R24*$B$10 -> #N/A | AC24: =N24*$C$6 -> 0 | AD24: =O24*$C$7 -> #N/A | AE24: =P24*$C$8 -> #N/A | AF24: =Q24*$C$9 -> #N/A | AG24: =R24*$C$10 -> #N/A | AH24: =(S24*S24+T24*T24+U24*U24+V24*V24+W24*W24)^0.5 -> 0 | AI24: =AH24*$B$14 -> 0 | AJ24: =SUM(X24:AB24) -> #N/A | AK24: =IF(AI24=0,0,AI24/AJ24) -> 0 | AL24: =AJ24/$B$2 -> #N/A
A25: Def2022 | B25: =IFERROR("$" & SUBSTITUTE(ADDRESS(1, MATCH(A25, INDIRECT("'" & $B$16 & "'!1:1"), 0), 4), "1", ""), "Not Found") -> $AM | C25: =COUNTIFS(INDIRECT("'" & $B$16 & "'!" & $B$17 & ":" & $B$17),C$18,INDIRECT("'" & $B$16 & "'!" & $B$18 & ":" & $B$18),$A25,INDIRECT("'" & $B$16 & "'!" & $B$12 & ":" & $B$12), "*" & $B$4 & "*") -> 0 | D25: =COUNTIFS(INDIRECT("'" & $B$16 & "'!" & $B$17 & ":" & $B$17),D$18,INDIRECT("'" & $B$16 & "'!" & $B$18 & ":" & $B$18),$A25,INDIRECT("'" & $B$16 & "'!" & $B$12 & ":" & $B$12), "*" & $B$4 & "*") -> 0 | E25: =COUNTIFS(INDIRECT("'" & $B$16 & "'!" & $B$17 & ":" & $B$17),E$18,INDIRECT("'" & $B$16 & "'!" & $B$18 & ":" & $B$18),$A25,INDIRECT("'" & $B$16 & "'!" & $B$12 & ":" & $B$12), "*" & $B$4 & "*") -> 0 | F25: =COUNTIFS(INDIRECT("'" & $B$16 & "'!" & $B$17 & ":" & $B$17),F$18,INDIRECT("'" & $B$16 & "'!" & $B$18 & ":" & $B$18),$A25,INDIRECT("'" & $B$16 & "'!" & $B$12 & ":" & $B$12), "*" & $B$4 & "*") -> 0 | G25: =COUNTIFS(INDIRECT("'" & $B$16 & "'!" & $B$17 & ":" & $B$17),G$18,INDIRECT("'" & $B$16 & "'!" & $B$18 & ":" & $B$18),$A25,INDIRECT("'" & $B$16 & "'!" & $B$12 & ":" & $B$12), "*" & $B$4 & "*") -> 0 | H25: =SUM(C25:G25) -> 0 | I25: =IFERROR(__xludf.DUMMYFUNCTION("IF($D$6=0, 0, VAR.S( FILTER( INDIRECT(""'"" & $B$16 & ""'!"" & $B25 & "":"" & $B25), (INDIRECT(""'"" & $B$16 & ""'!"" & $B$17 & "":"" & $B$17) = I$18) * (ISNUMBER(SEARCH($B$4, INDIRECT(""'"" & $B$16 & ""'!"&""" & $B$12 & "":"" & $B$12)))) ) ) / $D$6 ) "),0.0) -> 0 | J25: =IFERROR(__xludf.DUMMYFUNCTION("IF($D$7=0, 0, VAR.S( FILTER( INDIRECT(""'"" & $B$16 & ""'!"" & $B25 & "":"" & $B25), (INDIRECT(""'"" & $B$16 & ""'!"" & $B$17 & "":"" & $B$17) = J$18) * (ISNUMBER(SEARCH($B$4, INDIRECT(""'"" & $B$16 & ""'!"&""" & $B$12 & "":"" & $B$12)))) ) ) / $D$7 ) "),0.0) -> 0 | K25: =IFERROR(__xludf.DUMMYFUNCTION("IF($D$8=0, 0, VAR.S( FILTER( INDIRECT(""'"" & $B$16 & ""'!"" & $B25 & "":"" & $B25), (INDIRECT(""'"" & $B$16 & ""'!"" & $B$17 & "":"" & $B$17) = K$18) * (ISNUMBER(SEARCH($B$4, INDIRECT(""'"" & $B$16 & ""'!"&""" & $B$12 & "":"" & $B$12)))) ) ) / $D$8 ) "),0.0) -> 0 | L25: =IFERROR(__xludf.DUMMYFUNCTION("IF($D$9=0, 0, VAR.S( FILTER( INDIRECT(""'"" & $B$16 & ""'!"" & $B25 & "":"" & $B25), (INDIRECT(""'"" & $B$16 & ""'!"" & $B$17 & "":"" & $B$17) = L$18) * (ISNUMBER(SEARCH($B$4, INDIRECT(""'"" & $B$16 & ""'!"&""" & $B$12 & "":"" & $B$12)))) ) ) / $D$9 ) "),0.0) -> 0 | M25: =IFERROR(__xludf.DUMMYFUNCTION("IF($D$10=0, 0, VAR.S( FILTER( INDIRECT(""'"" & $B$16 & ""'!"" & $B25 & "":"" & $B25), (INDIRECT(""'"" & $B$16 & ""'!"" & $B$17 & "":"" & $B$17) = M$18) * (ISNUMBER(SEARCH($B$4, INDIRECT(""'"" & $B$16 & ""'!"&""" & $B$12 & "":"" & $B$12)))) ) ) / $D$10 ) "),0.0) -> 0 | N25: =IFERROR(__xludf.DUMMYFUNCTION("AVERAGE( FILTER( INDIRECT(""'"" & $B$16 & ""'!"" & $B25 & "":"" & $B25), (INDIRECT(""'"" & $B$16 & ""'!"" & $B$17 & "":"" & $B$17) = I$18) * (ISNUMBER(SEARCH($B$4, INDIRECT(""'"" & $B$16 & ""'!"" & $B$12 & "":"""&" & $B$12)))) ) )"),0.0) -> 0 | O25: =IFERROR(__xludf.DUMMYFUNCTION("AVERAGE( FILTER( INDIRECT(""'"" & $B$16 & ""'!"" & $B25 & "":"" & $B25), (INDIRECT(""'"" & $B$16 & ""'!"" & $B$17 & "":"" & $B$17) = J$18) * (ISNUMBER(SEARCH($B$4, INDIRECT(""'"" & $B$16 & ""'!"" & $B$12 & "":"""&" & $B$12)))) ) )"),"#N/A") -> #N/A | P25: =IFERROR(__xludf.DUMMYFUNCTION("AVERAGE( FILTER( INDIRECT(""'"" & $B$16 & ""'!"" & $B25 & "":"" & $B25), (INDIRECT(""'"" & $B$16 & ""'!"" & $B$17 & "":"" & $B$17) = K$18) * (ISNUMBER(SEARCH($B$4, INDIRECT(""'"" & $B$16 & ""'!"" & $B$12 & "":"""&" & $B$12)))) ) )"),"#N/A") -> #N/A | Q25: =IFERROR(__xludf.DUMMYFUNCTION("AVERAGE( FILTER( INDIRECT(""'"" & $B$16 & ""'!"" & $B25 & "":"" & $B25), (INDIRECT(""'"" & $B$16 & ""'!"" & $B$17 & "":"" & $B$17) = L$18) * (ISNUMBER(SEARCH($B$4, INDIRECT(""'"" & $B$16 & ""'!"" & $B$12 & "":"""&" & $B$12)))) ) )"),"#N/A") -> #N/A | R25: =IFERROR(__xludf.DUMMYFUNCTION("AVERAGE( FILTER( INDIRECT(""'"" & $B$16 & ""'!"" & $B25 & "":"" & $B25), (INDIRECT(""'"" & $B$16 & ""'!"" & $B$17 & "":"" & $B$17) = M$18) * (ISNUMBER(SEARCH($B$4, INDIRECT(""'"" & $B$16 & ""'!"" & $B$12 & "":"""&" & $B$12)))) ) )"),"#N/A") -> #N/A | S25: =($B$6^2*I25)^0.5 -> 0 | T25: =($B$7^2*J25)^0.5 -> 0 | U25: =($B$8^2*K25)^0.5 -> 0 | V25: =($B$9^2*L25)^0.5 -> 0 | W25: =($B$10^2*M25)^0.5 -> 0 | X25: =N25*$B$6 -> 0 | Y25: =O25*$B$7 -> #N/A | Z25: =P25*$B$8 -> #N/A | AA25: =Q25*$B$9 -> #N/A | AB25: =R25*$B$10 -> #N/A | AC25: =N25*$C$6 -> 0 | AD25: =O25*$C$7 -> #N/A | AE25: =P25*$C$8 -> #N/A | AF25: =Q25*$C$9 -> #N/A | AG25: =R25*$C$10 -> #N/A | AH25: =(S25*S25+T25*T25+U25*U25+V25*V25+W25*W25)^0.5 -> 0 | AI25: =AH25*$B$14 -> 0 | AJ25: =SUM(X25:AB25) -> #N/A | AK25: =IF(AI25=0,0,AI25/AJ25) -> 0 | AL25: =AJ25/$B$2 -> #N/A
H26: =SUM(H19:H25) -> 1 | AJ26: =SUM(AJ19:AJ25) -> #N/A
A27: Deg2016 | B27: =IFERROR("$" & SUBSTITUTE(ADDRESS(1, MATCH(A27, INDIRECT("'" & $B$16 & "'!1:1"), 0), 4), "1", ""), "Not Found") -> $AN | C27: =COUNTIFS(INDIRECT("'" & $B$16 & "'!" & $B$17 & ":" & $B$17),C$18,INDIRECT("'" & $B$16 & "'!" & $B$18 & ":" & $B$18),$A27,INDIRECT("'" & $B$16 & "'!" & $B$12 & ":" & $B$12), "*" & $B$4 & "*") -> 0 | D27: =COUNTIFS(INDIRECT("'" & $B$16 & "'!" & $B$17 & ":" & $B$17),D$18,INDIRECT("'" & $B$16 & "'!" & $B$18 & ":" & $B$18),$A27,INDIRECT("'" & $B$16 & "'!" & $B$12 & ":" & $B$12), "*" & $B$4 & "*") -> 0 | E27: =COUNTIFS(INDIRECT("'" & $B$16 & "'!" & $B$17 & ":" & $B$17),E$18,INDIRECT("'" & $B$16 & "'!" & $B$18 & ":" & $B$18),$A27,INDIRECT("'" & $B$16 & "'!" & $B$12 & ":" & $B$12), "*" & $B$4 & "*") -> 0 | F27: =COUNTIFS(INDIRECT("'" & $B$16 & "'!" & $B$17 & ":" & $B$17),F$18,INDIRECT("'" & $B$16 & "'!" & $B$18 & ":" & $B$18),$A27,INDIRECT("'" & $B$16 & "'!" & $B$12 & ":" & $B$12), "*" & $B$4 & "*") -> 0 | G27: =COUNTIFS(INDIRECT("'" & $B$16 & "'!" & $B$17 & ":" & $B$17),G$18,INDIRECT("'" & $B$16 & "'!" & $B$18 & ":" & $B$18),$A27,INDIRECT("'" & $B$16 & "'!" & $B$12 & ":" & $B$12), "*" & $B$4 & "*") -> 0 | H27: =SUM(C27:G27) -> 0 | I27: =IFERROR(__xludf.DUMMYFUNCTION("IF($D$6=0, 0, VAR.S( FILTER( INDIRECT(""'"" & $B$16 & ""'!"" & $B27 & "":"" & $B27), (INDIRECT(""'"" & $B$16 & ""'!"" & $B$17 & "":"" & $B$17) = I$18) * (ISNUMBER(SEARCH($B$4, INDIRECT(""'"" & $B$16 & ""'!"&""" & $B$12 & "":"" & $B$12)))) ) ) / $D$6 ) "),0.0) -> 0 | J27: =IFERROR(__xludf.DUMMYFUNCTION("IF($D$7=0, 0, VAR.S( FILTER( INDIRECT(""'"" & $B$16 & ""'!"" & $B27 & "":"" & $B27), (INDIRECT(""'"" & $B$16 & ""'!"" & $B$17 & "":"" & $B$17) = J$18) * (ISNUMBER(SEARCH($B$4, INDIRECT(""'"" & $B$16 & ""'!"&""" & $B$12 & "":"" & $B$12)))) ) ) / $D$7 ) "),0.0) -> 0 | K27: =IFERROR(__xludf.DUMMYFUNCTION("IF($D$8=0, 0, VAR.S( FILTER( INDIRECT(""'"" & $B$16 & ""'!"" & $B27 & "":"" & $B27), (INDIRECT(""'"" & $B$16 & ""'!"" & $B$17 & "":"" & $B$17) = K$18) * (ISNUMBER(SEARCH($B$4, INDIRECT(""'"" & $B$16 & ""'!"&""" & $B$12 & "":"" & $B$12)))) ) ) / $D$8 ) "),0.0) -> 0 | L27: =IFERROR(__xludf.DUMMYFUNCTION("IF($D$9=0, 0, VAR.S( FILTER( INDIRECT(""'"" & $B$16 & ""'!"" & $B27 & "":"" & $B27), (INDIRECT(""'"" & $B$16 & ""'!"" & $B$17 & "":"" & $B$17) = L$18) * (ISNUMBER(SEARCH($B$4, INDIRECT(""'"" & $B$16 & ""'!"&""" & $B$12 & "":"" & $B$12)))) ) ) / $D$9 ) "),0.0) -> 0 | M27: =IFERROR(__xludf.DUMMYFUNCTION("IF($D$10=0, 0, VAR.S( FILTER( INDIRECT(""'"" & $B$16 & ""'!"" & $B27 & "":"" & $B27), (INDIRECT(""'"" & $B$16 & ""'!"" & $B$17 & "":"" & $B$17) = M$18) * (ISNUMBER(SEARCH($B$4, INDIRECT(""'"" & $B$16 & ""'!"&""" & $B$12 & "":"" & $B$12)))) ) ) / $D$10 ) "),0.0) -> 0 | N27: =IFERROR(__xludf.DUMMYFUNCTION("AVERAGE( FILTER( INDIRECT(""'"" & $B$16 & ""'!"" & $B27 & "":"" & $B27), (INDIRECT(""'"" & $B$16 & ""'!"" & $B$17 & "":"" & $B$17) = I$18) * (ISNUMBER(SEARCH($B$4, INDIRECT(""'"" & $B$16 & ""'!"" & $B$12 & "":"""&" & $B$12)))) ) )"),0.0) -> 0 | O27: =IFERROR(__xludf.DUMMYFUNCTION("AVERAGE( FILTER( INDIRECT(""'"" & $B$16 & ""'!"" & $B27 & "":"" & $B27), (INDIRECT(""'"" & $B$16 & ""'!"" & $B$17 & "":"" & $B$17) = J$18) * (ISNUMBER(SEARCH($B$4, INDIRECT(""'"" & $B$16 & ""'!"" & $B$12 & "":"""&" & $B$12)))) ) )"),"#N/A") -> #N/A | P27: =IFERROR(__xludf.DUMMYFUNCTION("AVERAGE( FILTER( INDIRECT(""'"" & $B$16 & ""'!"" & $B27 & "":"" & $B27), (INDIRECT(""'"" & $B$16 & ""'!"" & $B$17 & "":"" & $B$17) = K$18) * (ISNUMBER(SEARCH($B$4, INDIRECT(""'"" & $B$16 & ""'!"" & $B$12 & "":"""&" & $B$12)))) ) )"),"#N/A") -> #N/A | Q27: =IFERROR(__xludf.DUMMYFUNCTION("AVERAGE( FILTER( INDIRECT(""'"" & $B$16 & ""'!"" & $B27 & "":"" & $B27), (INDIRECT(""'"" & $B$16 & ""'!"" & $B$17 & "":"" & $B$17) = L$18) * (ISNUMBER(SEARCH($B$4, INDIRECT(""'"" & $B$16 & ""'!"" & $B$12 & "":"""&" & $B$12)))) ) )"),"#N/A") -> #N/A | R27: =IFERROR(__xludf.DUMMYFUNCTION("AVERAGE( FILTER( INDIRECT(""'"" & $B$16 & ""'!"" & $B27 & "":"" & $B27), (INDIRECT(""'"" & $B$16 & ""'!"" & $B$17 & "":"" & $B$17) = M$18) * (ISNUMBER(SEARCH($B$4, INDIRECT(""'"" & $B$16 & ""'!"" & $B$12 & "":"""&" & $B$12)))) ) )"),"#N/A") -> #N/A | S27: =($B$6^2*I27)^0.5 -> 0 | T27: =($B$7^2*J27)^0.5 -> 0 | U27: =($B$8^2*K27)^0.5 -> 0 | V27: =($B$9^2*L27)^0.5 -> 0 | W27: =($B$10^2*M27)^0.5 -> 0 | X27: =N27*$B$6 -> 0 | Y27: =O27*$B$7 -> #N/A | Z27: =P27*$B$8 -> #N/A | AA27: =Q27*$B$9 -> #N/A | AB27: =R27*$B$10 -> #N/A | AC27: =N27*$C$6 -> 0 | AD27: =O27*$C$7 -> #N/A | AE27: =P27*$C$8 -> #N/A | AF27: =Q27*$C$9 -> #N/A | AG27: =R27*$C$10 -> #N/A | AH27: =(S27*S27+T27*T27+U27*U27+V27*V27+W27*W27)^0.5 -> 0 | AI27: =AH27*$B$14 -> 0 | AJ27: =SUM(X27:AB27) -> #N/A | AK27: =IF(AI27=0,0,AI27/AJ27) -> 0 | AL27: =AJ27/$B$2 -> #N/A
